# authentication error messages
authentication.err.validation.authenticator.notfound=Nie mo\u017cna wykona\u0107 uwierzytelniania, wystawca uwierzytelnienia o nazwie {0} nie zosta\u0142 znaleziony
authentication.err.validation.authenticator.notactive=Wystawca uwierzytelnienia jest nieaktywny

authentication.err.authentication=Nie mo\u017cna wykona\u0107 uwierzytelniania, nazwa u\u017cytkownika lub has\u0142o jest b\u0142\u0119dne. Nazwa u\u017cytkownika: {0}. Przyczyna: {1}
authentication.err.connection=Nie mo\u017cna po\u0142\u0105czy\u0107 si\u0119 z {0}. Przyczyna: {1}
authentication.err.communication=Nie mo\u017cna komunikowa\u0107 si\u0119 z {0}. Przyczyna: {1}

# LDAP error messages
authentication.err.connection.ldap.authenticator.unknownhost=Po\u0142\u0105czenie nie powiod\u0142o si\u0119, nieznany host LDAP: {0}
authentication.err.connection.ldap.user.notfound=Nie znaleziono u\u017cytkownika LDAP {0}
authentication.err.connection.ldap.manager.notfound=Nie znaleziono u\u017cytkownika zarz\u0105dzaj\u0105cego LDAP {0}
authentication.err.connection.ldap.search=Wyszukanie LDAP nie jest mo\u017cliwe. Przyczyna: {0}

# Authentication Diagnostic Steps
authentication.step.ldap.validation=Sprawdzanie poprawno\u015bci \u017c\u0105dania
authentication.step.ldap.connecting=Nawi\u0105zywanie po\u0142\u0105czenia z serwerem LDAP {0}
authentication.step.ldap.connected=Po\u0142\u0105czono z serwerem LDAP {0} z g\u0142\u00f3wnym: {1}
authentication.step.ldap.lookup=Identyfikator u\u017cytkownika testowego: {0} z zapytaniem: {1}
authentication.step.ldap.lookedup=Identyfikator u\u017cytkownika testowego: {0}; znaleziono nazw\u0119 wyr\u00f3\u017cniaj\u0105c\u0105 (DN): {1}
authentication.step.ldap.format.user=Podano format nazwy u\u017cytkownika, userNameFormat: {2}. U\u017cyj formatu identyfikatora u\u017cytkownika, userId: {0}, aby utworzy\u0107 nazw\u0119 wyr\u00f3\u017cniaj\u0105c\u0105 (DN): {1}
authentication.step.ldap.authentication=Uwierzytelnij identyfikator u\u017cytkownika: {0}


# Sync Summary message 
synchronization.summary.status=Przetworzono nast\u0119puj\u0105c\u0105 liczb\u0119 u\u017cytkownik\u00f3w: {0} i grup: {1}


# Error messages
authentication.ldap.validation.authenticator.notfound=Wystawca uwierzytelniania nie zosta\u0142 znaleziony

# Synchronization Diagnostic Steps
synchronization.step.users=Liczb znalezionych u\u017cytkownik\u00f3w: {0}
synchronization.step.groups=Liczb znalezionych grup: {0}
synchronization.step.users.lastsynced=Liczba ostatnio pomy\u015blnie zsynchronizowanych u\u017cytkownik\u00f3w: {0}
synchronization.step.groups.lastsynced=Liczba ostatnio pomy\u015blnie zsynchronizowanych grup: {0}

synchronization.err.ldap.search=Wyst\u0105pi\u0142 b\u0142\u0105d podczas wyszukiwania LDAP. Przyczyna: {0}
synchronization.err.ldap.get.user.id.missing=U\u017cytkownik nie ma atrybutu identyfikatora DN = {0}, attributeName = {1})
synchronization.err.ldap.get.group.id.missing=Grupa nie ma atrybutu identyfikatora DN = {0}, attributeName = {1})

synchronization.err.ldap.search.base.invalid=Nieprawid\u0142owa baza wyszukiwania {0}. Przyczyna: {1}

synchronization.err.ldap.group.member.missing.exception="Nie uda\u0142o si\u0119 ustali\u0107 cz\u0142onka grupy {0} za pomoc\u0105 nazwy wyr\u00f3\u017cniaj\u0105cej: {1}. Przyczyna: {2});
synchronization.err.ldap.group.member.missing="Nie uda\u0142o si\u0119 ustali\u0107 cz\u0142onka grupy {0} za pomoc\u0105 nazwy wyr\u00f3\u017cniaj\u0105cej: {1});







